Workbook

Sheet Repuestos
A1: ARTICULO | B1: DESCRIPCION | C1: CATEGORIA | D1: N# PARTE archivo | E1: N# PARTE 2 descripcion | F1: UBICACION | G1: MARCA | H1: SERIE | I1: MODELO | J1: VERSION | K1: APLICA A | L1: METRICA | M1: EXIST_VIRTUAL | N1: EXIST_FISICA | O1: FOTOS
A2: 215 | B2: CONDENSADOR | C2: FALT REP DFSK | F2: =IFERROR( VLOOKUP(A2,#REF!,2,0),"") | G2: {=_xlfn.XLOOKUP(I2,Base_Datos!D:D,Base_Datos!B:B,"")} -> DFSK | H2: {=IF(I2="","",IFERROR(_xlfn.XLOOKUP(I2,Base_Datos!$D$2:$D3876,Base_Datos!$C$2:$C3876),""))} -> Serie C | I2: C37 | J2: =IF(I2="","",IFERROR(VLOOKUP(I2,Base_Datos!$D$2:$E$72,2,0),"")) -> (1.5L) | M2: 0 | N2: 0
A3: 218 | B3: TABLERO | C3: FALT REP DFSK | D3: 8105000-CM02 | E3: 8105000-CM02 | F3: =IFERROR( VLOOKUP(A3,#REF!,2,0),"") | G3: {=_xlfn.XLOOKUP(I3,Base_Datos!D:D,Base_Datos!B:B,"")} -> DFSK | H3: {=IF(I3="","",IFERROR(_xlfn.XLOOKUP(I3,Base_Datos!$D$2:$D3876,Base_Datos!$C$2:$C3876),""))} -> Serie C | I3: C37 | J3: =IF(I3="","",IFERROR(VLOOKUP(I3,Base_Datos!$D$2:$E$72,2,0),"")) -> (1.5L) | M3: 0 | N3: 0
A4: 219 | B4: RADIO | C4: FALT REP DFSK | D4: 8105000-CM02 | E4: 8105000-CM02 | F4: =IFERROR( VLOOKUP(A4,#REF!,2,0),"") | G4: {=_xlfn.XLOOKUP(I4,Base_Datos!D:D,Base_Datos!B:B,"")} -> DFSK | H4: {=IF(I4="","",IFERROR(_xlfn.XLOOKUP(I4,Base_Datos!$D$2:$D3876,Base_Datos!$C$2:$C3876),""))} -> Serie C | I4: C37 | J4: =IF(I4="","",IFERROR(VLOOKUP(I4,Base_Datos!$D$2:$E$72,2,0),"")) -> (1.5L) | M4: 0 | N4: 0
A5: 220 | B5: TAPA VOLANTE ARRIBA | C5: FALT REP DFSK | D5: 1308100-CA02 | E5: 1308100-CA02 | F5: =IFERROR( VLOOKUP(A5,#REF!,2,0),"") | G5: {=_xlfn.XLOOKUP(I5,Base_Datos!D:D,Base_Datos!B:B,"")} -> DFSK | H5: {=IF(I5="","",IFERROR(_xlfn.XLOOKUP(I5,Base_Datos!$D$2:$D3876,Base_Datos!$C$2:$C3876),""))} -> Serie C | I5: C37 | J5: =IF(I5="","",IFERROR(VLOOKUP(I5,Base_Datos!$D$2:$E$72,2,0),"")) -> (1.5L) | M5: 0 | N5: 0
A6: 221 | B6: ALTERNADOR | C6: FALT REP DFSK | D6: 8105000-CM02 | E6: 8105000-CM02 | F6: =IFERROR( VLOOKUP(A6,#REF!,2,0),"") | G6: {=_xlfn.XLOOKUP(I6,Base_Datos!D:D,Base_Datos!B:B,"")} -> DFSK | H6: {=IF(I6="","",IFERROR(_xlfn.XLOOKUP(I6,Base_Datos!$D$2:$D3876,Base_Datos!$C$2:$C3876),""))} -> Serie C | I6: C37 | J6: =IF(I6="","",IFERROR(VLOOKUP(I6,Base_Datos!$D$2:$E$72,2,0),"")) -> (1.5L) | M6: 0 | N6: 0
A7: 222 | B7: ASIENTOS | C7: FALT REP DFSK | D7: 8105000-CM02 | E7: 8105000-CM02 | F7: =IFERROR( VLOOKUP(A7,#REF!,2,0),"") | G7: {=_xlfn.XLOOKUP(I7,Base_Datos!D:D,Base_Datos!B:B,"")} -> DFSK | H7: {=IF(I7="","",IFERROR(_xlfn.XLOOKUP(I7,Base_Datos!$D$2:$D3876,Base_Datos!$C$2:$C3876),""))} -> Serie C | I7: C37 | J7: =IF(I7="","",IFERROR(VLOOKUP(I7,Base_Datos!$D$2:$E$72,2,0),"")) -> (1.5L) | M7: 0 | N7: 0
A8: 223 | B8: PARACHOQUE DELANTERO COMPLETO | C8: FALT REP DFSK | D8: 8105000-CM02 | E8: 8105000-CM02 | F8: =IFERROR( VLOOKUP(A8,#REF!,2,0),"") | G8: {=_xlfn.XLOOKUP(I8,Base_Datos!D:D,Base_Datos!B:B,"")} -> DFSK | H8: {=IF(I8="","",IFERROR(_xlfn.XLOOKUP(I8,Base_Datos!$D$2:$D3876,Base_Datos!$C$2:$C3876),""))} -> Serie Glory | I8: G600 | J8: =IF(I8="","",IFERROR(VLOOKUP(I8,Base_Datos!$D$2:$E$72,2,0),"")) -> (1.5L) | M8: 0 | N8: 0
A9: 224 | B9: COMPUTADORA | C9: FALT REP DFSK | D9: 8105000-CM02 | E9: 8105000-CM02 | F9: =IFERROR( VLOOKUP(A9,#REF!,2,0),"") | G9: {=_xlfn.XLOOKUP(I9,Base_Datos!D:D,Base_Datos!B:B,"")} -> DFSK | H9: {=IF(I9="","",IFERROR(_xlfn.XLOOKUP(I9,Base_Datos!$D$2:$D3876,Base_Datos!$C$2:$C3876),""))} -> Serie Glory | I9: G600 | J9: =IF(I9="","",IFERROR(VLOOKUP(I9,Base_Datos!$D$2:$E$72,2,0),"")) -> (1.5L) | M9: 0 | N9: 0
A10: 225 | B10: MANGUERA CANISTER | C10: FALT REP DFSK | D10: 8105000-CM02 | E10: 8105000-CM02 | F10: =IFERROR( VLOOKUP(A10,#REF!,2,0),"") | G10: {=_xlfn.XLOOKUP(I10,Base_Datos!D:D,Base_Datos!B:B,"")} -> DFSK | H10: {=IF(I10="","",IFERROR(_xlfn.XLOOKUP(I10,Base_Datos!$D$2:$D3876,Base_Datos!$C$2:$C3876),""))} -> Serie Glory | I10: G600 | J10: =IF(I10="","",IFERROR(VLOOKUP(I10,Base_Datos!$D$2:$E$72,2,0),"")) -> (1.5L) | M10: 0 | N10: 0
A11: 226 | B11: BUJIAS | C11: FALT REP DFSK | D11: 8105000-CM02 | E11: 8105000-CM02 | F11: =IFERROR( VLOOKUP(A11,#REF!,2,0),"") | G11: {=_xlfn.XLOOKUP(I11,Base_Datos!D:D,Base_Datos!B:B,"")} -> DFSK | H11: {=IF(I11="","",IFERROR(_xlfn.XLOOKUP(I11,Base_Datos!$D$2:$D3876,Base_Datos!$C$2:$C3876),""))} -> Serie Glory | I11: G600 | J11: =IF(I11="","",IFERROR(VLOOKUP(I11,Base_Datos!$D$2:$E$72,2,0),"")) -> (1.5L) | M11: 0 | N11: 0
A12: 227 | B12: BOBINAS | C12: FALT REP DFSK | D12: 8105000-CM02 | E12: 8105000-CM02 | F12: =IFERROR( VLOOKUP(A12,#REF!,2,0),"") | G12: {=_xlfn.XLOOKUP(I12,Base_Datos!D:D,Base_Datos!B:B,"")} -> DFSK | H12: {=IF(I12="","",IFERROR(_xlfn.XLOOKUP(I12,Base_Datos!$D$2:$D3876,Base_Datos!$C$2:$C3876),""))} -> Serie Glory | I12: G600 | J12: =IF(I12="","",IFERROR(VLOOKUP(I12,Base_Datos!$D$2:$E$72,2,0),"")) -> (1.5L) | M12: 0 | N12: 0
A13: 228 | B13: RIEL DE INYECTORES | C13: FALT REP DFSK | D13: 8105000-CM02 | E13: 8105000-CM02 | F13: =IFERROR( VLOOKUP(A13,#REF!,2,0),"") | G13: {=_xlfn.XLOOKUP(I13,Base_Datos!D:D,Base_Datos!B:B,"")} -> DFSK | H13: {=IF(I13="","",IFERROR(_xlfn.XLOOKUP(I13,Base_Datos!$D$2:$D3876,Base_Datos!$C$2:$C3876),""))} -> Serie Glory | I13: G600 | J13: =IF(I13="","",IFERROR(VLOOKUP(I13,Base_Datos!$D$2:$E$72,2,0),"")) -> (1.5L) | M13: 0 | N13: 0
A14: 229 | B14: CUERPO DE ACELERACION | C14: FALT REP DFSK | D14: 8105000-CM02 | E14: 8105000-CM02 | F14: =IFERROR( VLOOKUP(A14,#REF!,2,0),"") | G14: {=_xlfn.XLOOKUP(I14,Base_Datos!D:D,Base_Datos!B:B,"")} -> DFSK | H14: {=IF(I14="","",IFERROR(_xlfn.XLOOKUP(I14,Base_Datos!$D$2:$D3876,Base_Datos!$C$2:$C3876),""))} -> Serie Glory | I14: G600 | J14: =IF(I14="","",IFERROR(VLOOKUP(I14,Base_Datos!$D$2:$E$72,2,0),"")) -> (1.5L) | M14: 0 | N14: 0
A15: 230 | B15: CORREA UNICA | C15: FALT REP DFSK | D15: 8105000-CM02 | E15: 8105000-CM02 | F15: =IFERROR( VLOOKUP(A15,#REF!,2,0),"") | G15: {=_xlfn.XLOOKUP(I15,Base_Datos!D:D,Base_Datos!B:B,"")} -> DFSK | H15: {=IF(I15="","",IFERROR(_xlfn.XLOOKUP(I15,Base_Datos!$D$2:$D3876,Base_Datos!$C$2:$C3876),""))} -> Serie Glory | I15: G600 | J15: =IF(I15="","",IFERROR(VLOOKUP(I15,Base_Datos!$D$2:$E$72,2,0),"")) -> (1.5L) | M15: 0 | N15: 0
A16: 231 | B16: TAPA LATERAL RETROVISOR | C16: FALT REP DFSK | D16: 8105000-CM02 | E16: 8105000-CM02 | F16: =IFERROR( VLOOKUP(A16,#REF!,2,0),"") | G16: {=_xlfn.XLOOKUP(I16,Base_Datos!D:D,Base_Datos!B:B,"")} -> DFSK | H16: {=IF(I16="","",IFERROR(_xlfn.XLOOKUP(I16,Base_Datos!$D$2:$D3876,Base_Datos!$C$2:$C3876),""))} -> Serie Glory | I16: G600 | J16: =IF(I16="","",IFERROR(VLOOKUP(I16,Base_Datos!$D$2:$E$72,2,0),"")) -> (1.5L) | M16: 0 | N16: 0
A17: 232 | B17: TABLERO | C17: FALT REP DFSK | D17: 8105000-CM02 | E17: 8105000-CM02 | F17: =IFERROR( VLOOKUP(A17,#REF!,2,0),"") | G17: {=_xlfn.XLOOKUP(I17,Base_Datos!D:D,Base_Datos!B:B,"")} -> DFSK | H17: {=IF(I17="","",IFERROR(_xlfn.XLOOKUP(I17,Base_Datos!$D$2:$D3876,Base_Datos!$C$2:$C3876),""))} -> Serie Glory | I17: G600 | J17: =IF(I17="","",IFERROR(VLOOKUP(I17,Base_Datos!$D$2:$E$72,2,0),"")) -> (1.5L) | M17: 0 | N17: 0
A18: 233 | B18: SISTEMA DE REPRODUCCION | C18: FALT REP DFSK | D18: 8105000-CM02 | E18: 8105000-CM02 | F18: =IFERROR( VLOOKUP(A18,#REF!,2,0),"") | G18: {=_xlfn.XLOOKUP(I18,Base_Datos!D:D,Base_Datos!B:B,"")} -> DFSK | H18: {=IF(I18="","",IFERROR(_xlfn.XLOOKUP(I18,Base_Datos!$D$2:$D3876,Base_Datos!$C$2:$C3876),""))} -> Serie Glory | I18: G600 | J18: =IF(I18="","",IFERROR(VLOOKUP(I18,Base_Datos!$D$2:$E$72,2,0),"")) -> (1.5L) | M18: 0 | N18: 0
A19: 234 | B19: PLATINA TRIANGULO RETROVISOR IZQUIERDA | C19: FALT REP DFSK | D19: 5504011-FS01 | E19: 5504011-FS01 | F19: =IFERROR( VLOOKUP(A19,#REF!,2,0),"") | G19: {=_xlfn.XLOOKUP(I19,Base_Datos!D:D,Base_Datos!B:B,"")} -> DFSK | H19: {=IF(I19="","",IFERROR(_xlfn.XLOOKUP(I19,Base_Datos!$D$2:$D3876,Base_Datos!$C$2:$C3876),""))} -> Serie Glory | I19: G500 ASPIRADA | J19: =IF(I19="","",IFERROR(VLOOKUP(I19,Base_Datos!$D$2:$E$72,2,0),"")) -> (1.5L) | K19: D51 - (1.5L) | M19: 0 | N19: 0
A20: 235 | B20: ESTRIBO DERECHO | C20: FALT REP DFSK | F20: =IFERROR( VLOOKUP(A20,#REF!,2,0),"") | G20: {=_xlfn.XLOOKUP(I20,Base_Datos!D:D,Base_Datos!B:B,"")} -> DFSK | H20: {=IF(I20="","",IFERROR(_xlfn.XLOOKUP(I20,Base_Datos!$D$2:$D3876,Base_Datos!$C$2:$C3876),""))} -> Serie Glory | I20: G500 ASPIRADA | J20: =IF(I20="","",IFERROR(VLOOKUP(I20,Base_Datos!$D$2:$E$72,2,0),"")) -> (1.5L) | K20: D51 - (1.5L) | M20: 0 | N20: 0
A21: 236 | B21: REPRODUCTOR | C21: FALT REP DFSK | F21: =IFERROR( VLOOKUP(A21,#REF!,2,0),"") | G21: {=_xlfn.XLOOKUP(I21,Base_Datos!D:D,Base_Datos!B:B,"")} -> DFSK | H21: {=IF(I21="","",IFERROR(_xlfn.XLOOKUP(I21,Base_Datos!$D$2:$D3876,Base_Datos!$C$2:$C3876),""))} -> Serie K | I21: K01S | J21: =IF(I21="","",IFERROR(VLOOKUP(I21,Base_Datos!$D$2:$E$72,2,0),"")) -> (1.1L) | M21: 0 | N21: 0
A22: 237 | B22: LATERALES DE CAVA DERECHO | C22: FALT REP DFSK | F22: =IFERROR( VLOOKUP(A22,#REF!,2,0),"") | G22: {=_xlfn.XLOOKUP(I22,Base_Datos!D:D,Base_Datos!B:B,"")} -> DFSK | H22: {=IF(I22="","",IFERROR(_xlfn.XLOOKUP(I22,Base_Datos!$D$2:$D3876,Base_Datos!$C$2:$C3876),""))} -> Serie K | I22: K01S | J22: =IF(I22="","",IFERROR(VLOOKUP(I22,Base_Datos!$D$2:$E$72,2,0),"")) -> (1.1L) | K22: D1 - (2.4L) | M22: 0 | N22: 0
A23: 238 | B23: LATERALES DE CAVA IZQUIERDO | C23: FALT REP DFSK | F23: =IFERROR( VLOOKUP(A23,#REF!,2,0),"") | G23: {=_xlfn.XLOOKUP(I23,Base_Datos!D:D,Base_Datos!B:B,"")} -> DFSK | H23: {=IF(I23="","",IFERROR(_xlfn.XLOOKUP(I23,Base_Datos!$D$2:$D3876,Base_Datos!$C$2:$C3876),""))} -> Serie K | I23: K01S | J23: =IF(I23="","",IFERROR(VLOOKUP(I23,Base_Datos!$D$2:$E$72,2,0),"")) -> (1.1L) | K23: D1 - (2.4L) | M23: 0 | N23: 0
A24: 239 | B24: PARABRISAS TRASERO | C24: FALT REP DFSK | F24: =IFERROR( VLOOKUP(A24,#REF!,2,0),"") | G24: {=_xlfn.XLOOKUP(I24,Base_Datos!D:D,Base_Datos!B:B,"")} -> DFSK | H24: {=IF(I24="","",IFERROR(_xlfn.XLOOKUP(I24,Base_Datos!$D$2:$D3876,Base_Datos!$C$2:$C3876),""))} -> Serie K | I24: K01S | J24: =IF(I24="","",IFERROR(VLOOKUP(I24,Base_Datos!$D$2:$E$72,2,0),"")) -> (1.1L) | K24: D1 - (2.4L) | M24: 0 | N24: 0
A25: 240 | B25: PUERTA IZQUIERDA | C25: FALT REP DFSK | D25: 6201100-FS01D | E25: 6201100-FS01D | F25: =IFERROR( VLOOKUP(A25,#REF!,2,0),"") | G25: {=_xlfn.XLOOKUP(I25,Base_Datos!D:D,Base_Datos!B:B,"")} -> DFSK | H25: {=IF(I25="","",IFERROR(_xlfn.XLOOKUP(I25,Base_Datos!$D$2:$D3876,Base_Datos!$C$2:$C3876),""))} -> Serie K | I25: K01S | J25: =IF(I25="","",IFERROR(VLOOKUP(I25,Base_Datos!$D$2:$E$72,2,0),"")) -> (1.1L) | M25: 0 | N25: 0
A26: 241 | B26: PUERTA DERECHA | C26: FALT REP DFSK | D26: 6201100-FS01D | E26: 6201100-FS01D | F26: =IFERROR( VLOOKUP(A26,#REF!,2,0),"") | G26: {=_xlfn.XLOOKUP(I26,Base_Datos!D:D,Base_Datos!B:B,"")} -> DFSK | H26: {=IF(I26="","",IFERROR(_xlfn.XLOOKUP(I26,Base_Datos!$D$2:$D3876,Base_Datos!$C$2:$C3876),""))} -> Serie K | I26: K01S | J26: =IF(I26="","",IFERROR(VLOOKUP(I26,Base_Datos!$D$2:$E$72,2,0),"")) -> (1.1L) | M26: 0 | N26: 0
A27: 242 | B27: PARRILLA DELANTERA | C27: FALT REP DFSK | D27: 6201100-FS01D | E27: 6201100-FS01D | F27: =IFERROR( VLOOKUP(A27,#REF!,2,0),"") | G27: {=_xlfn.XLOOKUP(I27,Base_Datos!D:D,Base_Datos!B:B,"")} -> DFSK | H27: {=IF(I27="","",IFERROR(_xlfn.XLOOKUP(I27,Base_Datos!$D$2:$D3876,Base_Datos!$C$2:$C3876),""))} -> Serie K | I27: K01S | J27: =IF(I27="","",IFERROR(VLOOKUP(I27,Base_Datos!$D$2:$E$72,2,0),"")) -> (1.1L) | M27: 0 | N27: 0
A28: 243 | B28: BOMBA DE FRENO | C28: FALT REP DFSK | D28: 6201100-FS01D | E28: 6201100-FS01D | F28: =IFERROR( VLOOKUP(A28,#REF!,2,0),"") | G28: {=_xlfn.XLOOKUP(I28,Base_Datos!D:D,Base_Datos!B:B,"")} -> DFSK | H28: {=IF(I28="","",IFERROR(_xlfn.XLOOKUP(I28,Base_Datos!$D$2:$D3876,Base_Datos!$C$2:$C3876),""))} -> Serie K | I28: K01S | J28: =IF(I28="","",IFERROR(VLOOKUP(I28,Base_Datos!$D$2:$E$72,2,0),"")) -> (1.1L) | M28: 0 | N28: 0
A29: 244 | B29: SENSOR DE CIGÜEÑAL | C29: FALT REP DFSK | D29: 6201100-FS01D | E29: 6201100-FS01D | F29: =IFERROR( VLOOKUP(A29,#REF!,2,0),"") | G29: {=_xlfn.XLOOKUP(I29,Base_Datos!D:D,Base_Datos!B:B,"")} -> DFSK | H29: {=IF(I29="","",IFERROR(_xlfn.XLOOKUP(I29,Base_Datos!$D$2:$D3876,Base_Datos!$C$2:$C3876),""))} -> Serie K | I29: K01S | J29: =IF(I29="","",IFERROR(VLOOKUP(I29,Base_Datos!$D$2:$E$72,2,0),"")) -> (1.1L) | M29: 0 | N29: 0
A30: 245 | B30: EVAPORADOR | C30: FALT REP DFSK | F30: =IFERROR( VLOOKUP(A30,#REF!,2,0),"") | G30: {=_xlfn.XLOOKUP(I30,Base_Datos!D:D,Base_Datos!B:B,"")} -> DFSK | H30: {=IF(I30="","",IFERROR(_xlfn.XLOOKUP(I30,Base_Datos!$D$2:$D3876,Base_Datos!$C$2:$C3876),""))} -> Serie C | I30: C37 | J30: =IF(I30="","",IFERROR(VLOOKUP(I30,Base_Datos!$D$2:$E$72,2,0),"")) -> (1.5L) | M30: 0 | N30: 0
A31: 246 | B31: MANILLA PUERTA DELANTERA DERECHA INTERNA | C31: FALT REP DFSK | F31: =IFERROR( VLOOKUP(A31,#REF!,2,0),"") | G31: {=_xlfn.XLOOKUP(I31,Base_Datos!D:D,Base_Datos!B:B,"")} -> DFSK | H31: {=IF(I31="","",IFERROR(_xlfn.XLOOKUP(I31,Base_Datos!$D$2:$D3876,Base_Datos!$C$2:$C3876),""))} -> Serie C | I31: C37 | J31: =IF(I31="","",IFERROR(VLOOKUP(I31,Base_Datos!$D$2:$E$72,2,0),"")) -> (1.5L) | M31: 0 | N31: 0
A32: 247 | B32: MANILLA PUERTA DELANTERA IZQUIERDA INTERNA | C32: FALT REP DFSK | F32: =IFERROR( VLOOKUP(A32,#REF!,2,0),"") | G32: {=_xlfn.XLOOKUP(I32,Base_Datos!D:D,Base_Datos!B:B,"")} -> DFSK | H32: {=IF(I32="","",IFERROR(_xlfn.XLOOKUP(I32,Base_Datos!$D$2:$D3876,Base_Datos!$C$2:$C3876),""))} -> Serie C | I32: C37 | J32: =IF(I32="","",IFERROR(VLOOKUP(I32,Base_Datos!$D$2:$E$72,2,0),"")) -> (1.5L) | M32: 0 | N32: 0
A33: 248 | B33: TENSOR DE CORREA UNICA | C33: FALT REP DFSK | D33: 2909200-01 | E33: 2909200-01 | F33: =IFERROR( VLOOKUP(A33,#REF!,2,0),"") | G33: {=_xlfn.XLOOKUP(I33,Base_Datos!D:D,Base_Datos!B:B,"")} -> DFSK | H33: {=IF(I33="","",IFERROR(_xlfn.XLOOKUP(I33,Base_Datos!$D$2:$D3876,Base_Datos!$C$2:$C3876),""))} -> Serie D | I33: D1 | J33: =IF(I33="","",IFERROR(VLOOKUP(I33,Base_Datos!$D$2:$E$72,2,0),"")) -> (2.4L) | K33: G330 - (1.5L) | M33: 0 | N33: 0
A34: 249 | B34: ARNES PRIMARIO DE MOTOR | C34: FALT REP DFSK | D34: 2909200-01 | E34: 2909200-01 | F34: =IFERROR( VLOOKUP(A34,#REF!,2,0),"") | G34: {=_xlfn.XLOOKUP(I34,Base_Datos!D:D,Base_Datos!B:B,"")} -> DFSK | H34: {=IF(I34="","",IFERROR(_xlfn.XLOOKUP(I34,Base_Datos!$D$2:$D3876,Base_Datos!$C$2:$C3876),""))} -> Serie D | I34: D1 | J34: =IF(I34="","",IFERROR(VLOOKUP(I34,Base_Datos!$D$2:$E$72,2,0),"")) -> (2.4L) | K34: G330 - (1.5L) | M34: 0 | N34: 0
A35: 250 | B35: ARNES DE MOTOR | C35: FALT REP DFSK | D35: 2909200-01 | E35: 2909200-01 | F35: =IFERROR( VLOOKUP(A35,#REF!,2,0),"") | G35: {=_xlfn.XLOOKUP(I35,Base_Datos!D:D,Base_Datos!B:B,"")} -> DFSK | H35: {=IF(I35="","",IFERROR(_xlfn.XLOOKUP(I35,Base_Datos!$D$2:$D3876,Base_Datos!$C$2:$C3876),""))} -> Serie D | I35: D1 | J35: =IF(I35="","",IFERROR(VLOOKUP(I35,Base_Datos!$D$2:$E$72,2,0),"")) -> (2.4L) | K35: G330 - (1.5L) | M35: 0 | N35: 0
A36: 251 | B36: ENVASE DE REFRIGERANTE | C36: FALT REP DFSK | D36: 2909200-01 | E36: 2909200-01 | F36: =IFERROR( VLOOKUP(A36,#REF!,2,0),"") | G36: {=_xlfn.XLOOKUP(I36,Base_Datos!D:D,Base_Datos!B:B,"")} -> DFSK | H36: {=IF(I36="","",IFERROR(_xlfn.XLOOKUP(I36,Base_Datos!$D$2:$D3876,Base_Datos!$C$2:$C3876),""))} -> Serie D | I36: D1 | J36: =IF(I36="","",IFERROR(VLOOKUP(I36,Base_Datos!$D$2:$E$72,2,0),"")) -> (2.4L) | K36: G330 - (1.5L) | M36: 0 | N36: 0
A37: 252 | B37: BOBINA DE IGNICION | C37: FALT REP DFSK | D37: 2909200-01 | E37: 2909200-01 | F37: =IFERROR( VLOOKUP(A37,#REF!,2,0),"") | G37: {=_xlfn.XLOOKUP(I37,Base_Datos!D:D,Base_Datos!B:B,"")} -> DFSK | H37: {=IF(I37="","",IFERROR(_xlfn.XLOOKUP(I37,Base_Datos!$D$2:$D3876,Base_Datos!$C$2:$C3876),""))} -> Serie D | I37: D1 | J37: =IF(I37="","",IFERROR(VLOOKUP(I37,Base_Datos!$D$2:$E$72,2,0),"")) -> (2.4L) | K37: G330 - (1.5L) | M37: 0 | N37: 0
A38: 253 | B38: MODULO IPDM | C38: FALT REP DFSK | D38: 2909200-01 | E38: 2909200-01 | F38: =IFERROR( VLOOKUP(A38,#REF!,2,0),"") | G38: {=_xlfn.XLOOKUP(I38,Base_Datos!D:D,Base_Datos!B:B,"")} -> DFSK | H38: {=IF(I38="","",IFERROR(_xlfn.XLOOKUP(I38,Base_Datos!$D$2:$D3876,Base_Datos!$C$2:$C3876),""))} -> Serie D | I38: D1 | J38: =IF(I38="","",IFERROR(VLOOKUP(I38,Base_Datos!$D$2:$E$72,2,0),"")) -> (2.4L) | K38: G330 - (1.5L) | M38: 0 | N38: 0
A39: 254 | B39: CARDAN MEDIO | C39: FALT REP DFSK | D39: 2909200-01 | E39: 2909200-01 | F39: =IFERROR( VLOOKUP(A39,#REF!,2,0),"") | G39: {=_xlfn.XLOOKUP(I39,Base_Datos!D:D,Base_Datos!B:B,"")} -> DFSK | H39: {=IF(I39="","",IFERROR(_xlfn.XLOOKUP(I39,Base_Datos!$D$2:$D3876,Base_Datos!$C$2:$C3876),""))} -> Serie D | I39: D1 | J39: =IF(I39="","",IFERROR(VLOOKUP(I39,Base_Datos!$D$2:$E$72,2,0),"")) -> (2.4L) | K39: G330 - (1.5L) | M39: 0 | N39: 0
A40: 255 | B40: CARDAN TRASERO | C40: FALT REP DFSK | D40: 2909200-01 | E40: 2909200-01 | F40: =IFERROR( VLOOKUP(A40,#REF!,2,0),"") | G40: {=_xlfn.XLOOKUP(I40,Base_Datos!D:D,Base_Datos!B:B,"")} -> DFSK | H40: {=IF(I40="","",IFERROR(_xlfn.XLOOKUP(I40,Base_Datos!$D$2:$D3876,Base_Datos!$C$2:$C3876),""))} -> Serie D | I40: D1 | J40: =IF(I40="","",IFERROR(VLOOKUP(I40,Base_Datos!$D$2:$E$72,2,0),"")) -> (2.4L) | K40: G330 - (1.5L) | M40: 0 | N40: 0
...

Sheet Base_Datos
A1: CATEGORIA | B1: MARCA | C1: SERIE | D1: MODELO | E1: VERSION | F1: MARCA / MODELO | G1: MARCA / SERIE | H1: MODELO / VERSION | I1: METRICA
A2: BLUESKY | B2: DFSK | C2: Serie K | D2: K01S | E2: (1.1L) | F2: =B2&" - "&D2 -> DFSK - K01S | G2: =B2&" - "&C2 -> DFSK - Serie K | H2: =D2&" - "&E2 -> K01S - (1.1L) | I2: PIEZA
A3: REPUESTOS NACIONALES/PLAZA | B3: DFSK | C3: Serie K | D3: K01S | E3: (1.2L) | F3: =B3&" - "&D3 -> DFSK - K01S | G3: =B3&" - "&C3 -> DFSK - Serie K | H3: =D3&" - "&E3 -> K01S - (1.2L) | I3: JUEGO / KIT
A4: ELEMENTOS ENSAMBLE | B4: DFSK | C4: Serie K | D4: K02S | E4: (1.1L) | F4: =B4&" - "&D4 -> DFSK - K02S | G4: =B4&" - "&C4 -> DFSK - Serie K | H4: =D4&" - "&E4 -> K02S - (1.1L) | I4: PAR
A5: DFSK | B5: DFSK | C5: Serie K | D5: K05 | E5: (1.1L) | F5: =B5&" - "&D5 -> DFSK - K05 | G5: =B5&" - "&C5 -> DFSK - Serie K | H5: =D5&" - "&E5 -> K05 - (1.1L) | I5: LITROS
A6: FALT REP DFSK | B6: DFSK | C6: Serie K | D6: K07 | E6: (1.1L) | F6: =B6&" - "&D6 -> DFSK - K07 | G6: =B6&" - "&C6 -> DFSK - Serie K | H6: =D6&" - "&E6 -> K07 - (1.1L) | I6: CUARTO (QT)
A7: FALT REP GAC | B7: DFSK | C7: Serie C | D7: C31 | E7: (1.5L) | F7: =B7&" - "&D7 -> DFSK - C31 | G7: =B7&" - "&C7 -> DFSK - Serie C | H7: =D7&" - "&E7 -> C31 - (1.5L) | I7: GALÓN
A8: SHINERAY | B8: DFSK | C8: Serie C | D8: C32 | E8: (1.5L) | F8: =B8&" - "&D8 -> DFSK - C32 | G8: =B8&" - "&C8 -> DFSK - Serie C | H8: =D8&" - "&E8 -> C32 - (1.5L) | I8: CUÑETE (5 GAL)
A9: DONGFENG | B9: DFSK | C9: Serie D | D9: D1 | E9: (2.4L) | F9: =B9&" - "&D9 -> DFSK - D1 | G9: =B9&" - "&C9 -> DFSK - Serie D | H9: =D9&" - "&E9 -> D1 - (2.4L) | I9: TAMBOR (55 GAL)
A10: RETOMAS | B10: DFSK | C10: Serie C | D10: C35 | E10: (1.5L) | F10: =B10&" - "&D10 -> DFSK - C35 | G10: =B10&" - "&C10 -> DFSK - Serie C | H10: =D10&" - "&E10 -> C35 - (1.5L) | I10: SPRAY / AEROSOL
A11: GAC | B11: DFSK | C11: Serie C | D11: C37 | E11: (1.5L) | F11: =B11&" - "&D11 -> DFSK - C37 | G11: =B11&" - "&C11 -> DFSK - Serie C | H11: =D11&" - "&E11 -> C37 - (1.5L) | I11: TUBO / CARTUCHO
A12: FAW | B12: DFSK | C12: Serie Glory | D12: G500 TURBO | E12: (1.5L) | F12: =B12&" - "&D12 -> DFSK - G500 TURBO | G12: =B12&" - "&C12 -> DFSK - Serie Glory | H12: =D12&" - "&E12 -> G500 TURBO - (1.5L) | I12: POTE / ENVASE
A13: MATERIAL POP | B13: DFSK | C13: Serie Glory | D13: G500 ASPIRADA | E13: (1.5L) | F13: =B13&" - "&D13 -> DFSK - G500 ASPIRADA | G13: =B13&" - "&C13 -> DFSK - Serie Glory | H13: =D13&" - "&E13 -> G500 ASPIRADA - (1.5L) | I13: METRO
... A16: COSTEO/ENSAMBLE/GGOO | B16: DFSK | C16: Serie Glory | D16: G560 | E16: (1.8L) | F16: =B16&" - "&D16 -> DFSK - G560 | G16: =B16&" - "&C16 -> DFSK - Serie Glory | H16: =D16&" - "&E16 -> G560 - (1.8L) | I16: UNIDAD
A17: REPUESTOS | B17: DFSK | C17: Serie Glory | D17: G330 | E17: (1.5L) | F17: =B17&" - "&D17 -> DFSK - G330 | G17: =B17&" - "&C17 -> DFSK - Serie Glory | H17: =D17&" - "&E17 -> G330 - (1.5L)
A18: REPUESTOS GAC | B18: DFSK | C18: Serie Glory | D18: G580 | E18: (1.5L) | F18: =B18&" - "&D18 -> DFSK - G580 | G18: =B18&" - "&C18 -> DFSK - Serie Glory | H18: =D18&" - "&E18 -> G580 - (1.5L)
A19: LATONERIA Y PINTURA | B19: DFSK | C19: Serie Glory | D19: G560 | E19: (1.5L) | F19: =B19&" - "&D19 -> DFSK - G560 | G19: =B19&" - "&C19 -> DFSK - Serie Glory | H19: =D19&" - "&E19 -> G560 - (1.5L)
A20: REPUESTOS DFSK | B20: DFSK | C20: Serie D | D20: D51 | E20: (1.5L) | F20: =B20&" - "&D20 -> DFSK - D51 | G20: =B20&" - "&C20 -> DFSK - Serie D | H20: =D20&" - "&E20 -> D51 - (1.5L)
A21: REPUESTOS SHINERAY | B21: DFSK | C21: Serie D | D21: D71 | E21: (1.5L) | F21: =B21&" - "&D21 -> DFSK - D71 | G21: =B21&" - "&C21 -> DFSK - Serie D | H21: =D21&" - "&E21 -> D71 - (1.5L)
A22: REPUESTOS REBITTE | B22: DFSK | C22: Serie D | D22: D72 | E22: (1.5L) | F22: =B22&" - "&D22 -> DFSK - D72 | G22: =B22&" - "&C22 -> DFSK - Serie D | H22: =D22&" - "&E22 -> D72 - (1.5L)
A23: REPUESTOS REBATTE | B23: DFSK | C23: Serie IX | D23: IX5 | E23: (1.5L) | F23: =B23&" - "&D23 -> DFSK - IX5 | G23: =B23&" - "&C23 -> DFSK - Serie IX | H23: =D23&" - "&E23 -> IX5 - (1.5L)
A24: REPUESTOS - GLORY 500 | B24: GAC | C24: Serie Smilodon | D24: SMILODON SE | E24: (2.4L) | F24: =B24&" - "&D24 -> GAC - SMILODON SE | G24: =B24&" - "&C24 -> GAC - Serie Smilodon | H24: =D24&" - "&E24 -> SMILODON SE - (2.4L)
A25: REPUESTOS - SERIE K | B25: GAC | C25: Serie S | D25: S7 | E25: (1.5L) | F25: =B25&" - "&D25 -> GAC - S7 | G25: =B25&" - "&C25 -> GAC - Serie S | H25: =D25&" - "&E25 -> S7 - (1.5L)
A26: ESTACAS/CISTERNA | B26: GAC | C26: Serie GS | D26: GS8 | E26: (2.0L) | F26: =B26&" - "&D26 -> GAC - GS8 | G26: =B26&" - "&C26 -> GAC - Serie GS | H26: =D26&" - "&E26 -> GS8 - (2.0L)
A27: REPUESTOS "DESUSO" | B27: GAC | C27: Serie Empow | D27: EMPOW 2.0 | E27: (2.0L) | F27: =B27&" - "&D27 -> GAC - EMPOW 2.0 | G27: =B27&" - "&C27 -> GAC - Serie Empow | H27: =D27&" - "&E27 -> EMPOW 2.0 - (2.0L)
A28: REPUESTOS GRUA | B28: GAC | C28: Serie Emzoom | D28: EMZOOM R STYLE | E28: (1.5L) | F28: =B28&" - "&D28 -> GAC - EMZOOM R STYLE | G28: =B28&" - "&C28 -> GAC - Serie Emzoom | H28: =D28&" - "&E28 -> EMZOOM R STYLE - (1.5L)
A29: VEHICULO | B29: GAC | C29: Serie Empow | D29: EMPOW | E29: (1.5L) | F29: =B29&" - "&D29 -> GAC - EMPOW | G29: =B29&" - "&C29 -> GAC - Serie Empow | H29: =D29&" - "&E29 -> EMPOW - (1.5L)
B30: GAC | C30: Serie Smilodon | D30: SMILODON B PRO | E30: (2.4L) | F30: =B30&" - "&D30 -> GAC - SMILODON B PRO | G30: =B30&" - "&C30 -> GAC - Serie Smilodon | H30: =D30&" - "&E30 -> SMILODON B PRO - (2.4L)
B31: GAC | C31: Serie Emzoom | D31: EMZOOM | E31: (1.5L) | F31: =B31&" - "&D31 -> GAC - EMZOOM | G31: =B31&" - "&C31 -> GAC - Serie Emzoom | H31: =D31&" - "&E31 -> EMZOOM - (1.5L)
B32: GAC | C32: Serie Aion | D32: AION UT | E32: (EV) | F32: =B32&" - "&D32 -> GAC - AION UT | G32: =B32&" - "&C32 -> GAC - Serie Aion | H32: =D32&" - "&E32 -> AION UT - (EV)
B33: GAC | C33: Serie Smilodon | D33: SMILODON SE | E33: (2.8L) | F33: =B33&" - "&D33 -> GAC - SMILODON SE | G33: =B33&" - "&C33 -> GAC - Serie Smilodon | H33: =D33&" - "&E33 -> SMILODON SE - (2.8L)
B34: GAC | C34: Serie GS | D34: GS3 | E34: (1.5L) | F34: =B34&" - "&D34 -> GAC - GS3 | G34: =B34&" - "&C34 -> GAC - Serie GS | H34: =D34&" - "&E34 -> GS3 - (1.5L)
B35: SHINERAY | C35: Serie T | D35: T30 | E35: (1.6L) | F35: =B35&" - "&D35 -> SHINERAY - T30 | G35: =B35&" - "&C35 -> SHINERAY - Serie T | H35: =D35&" - "&E35 -> T30 - (1.6L)
B36: SHINERAY | C36: Serie T | D36: T32 | E36: (1.6L) | F36: =B36&" - "&D36 -> SHINERAY - T32 | G36: =B36&" - "&C36 -> SHINERAY - Serie T | H36: =D36&" - "&E36 -> T32 - (1.6L)
B37: SHINERAY | C37: Serie X30 | D37: X30L CARGA | E37: (1.5L) | F37: =B37&" - "&D37 -> SHINERAY - X30L CARGA | G37: =B37&" - "&C37 -> SHINERAY - Serie X30 | H37: =D37&" - "&E37 -> X30L CARGA - (1.5L)
B38: SHINERAY | C38: Serie X30 | D38: X30L PASAJEROS | E38: (1.5L) | F38: =B38&" - "&D38 -> SHINERAY - X30L PASAJEROS | G38: =B38&" - "&C38 -> SHINERAY - Serie X30 | H38: =D38&" - "&E38 -> X30L PASAJEROS - (1.5L)
B39: SHINERAY | C39: Serie T | D39: T30 | E39: (1.5L) | F39: =B39&" - "&D39 -> SHINERAY - T30 | G39: =B39&" - "&C39 -> SHINERAY - Serie T | H39: =D39&" - "&E39 -> T30 - (1.5L)
B40: SHINERAY | C40: Serie T | D40: T32 | E40: (1.5L) | F40: =B40&" - "&D40 -> SHINERAY - T32 | G40: =B40&" - "&C40 -> SHINERAY - Serie T | H40: =D40&" - "&E40 -> T32 - (1.5L)
B41: SHINERAY | C41: Serie X30 | D41: X30L CARGA | E41: (1.6L) | F41: =B41&" - "&D41 -> SHINERAY - X30L CARGA | G41: =B41&" - "&C41 -> SHINERAY - Serie X30 | H41: =D41&" - "&E41 -> X30L CARGA - (1.6L)
... B64: MOTUL | C64: MOTOR | D64: 20W-50 | E64: MINERAL | F64: =B64&" - "&D64 -> MOTUL - 20W-50 | G64: =B64&" - "&C64 -> MOTUL - MOTOR | H64: =D64&" - "&E64 -> 20W-50 - MINERAL
...
